Workbook

Sheet Start Here
A1: DPDP Obligations Matrix: gap analysis workbook (version 3, 15 October 2026)
A2: Digital Personal Data Protection Act, 2023 and Digital Personal Data Protection Rules, 2025 (G.S.R. 846(E), 13 November 2025). A working tool for gap analysis. It is not legal advice.
C3: Days remaining
A4: Today's date | B4: =TODAY()
A5: Consent Manager registration opens (Rule 4 comes into force) | B5: 46339 | C5: =MAX(0,B5-$B$4)
A6: Main obligations apply (Rules 3, 5 to 16, 22 and 23 come into force) | B6: 46520 | C6: =MAX(0,B6-$B$4)
A9: HOW THE CONTROL IDENTIFIERS ARE BUILT
A10: Every control identifier is taken from the law's own numbering, so anyone can check it against the Gazette.
A11: DPDP-Act-S8(5) means Section 8(5) of the Digital Personal Data Protection Act, 2023.
A12: DPDP-Rule-7(2) means Rule 7(2) of the Digital Personal Data Protection Rules, 2025.
A13: Where one control draws on several provisions, the identifier uses the main provision and the others are listed in the column 'Other related provisions'.
A14: Where one duty draws on several provisions, the column 'Provisions covered in this row' names every section, sub-section, Rule and Schedule that the row is responsible for. 'Other related provisions' lists only other rows to read alongside it.
A15: A provision has its own row only if a company could meet it while failing the provisions next to it, and it needs a different owner or different evidence. Otherwise it is grouped and named in 'Provisions covered in this row'. For this reason each clause of Rule 6(1) has its own row.
A16: The sheet 'Coverage' lists every section of the Act, every Rule and every Schedule, and shows the row that covers it or why it does not apply to companies.
A17: The earlier working codes (for example LAW-01, SEC-01) are retired. The sheet 'Identifier Change Log' records every change, including those in version 3.
A19: WHEN THE ACT APPLIES (SECTION 3)
A20: The Act applies to digital personal data processed in India, and to processing outside India where it is connected with offering goods or services to people in India. It does not apply to data processed by an individual for personal or domestic purposes, or to data made publicly available by the person herself or under a legal obligation. Confirm that the Act applies before using this workbook.
A22: HOW TO USE THIS WORKBOOK
... A42: The dates on which individual sections of the Act come into force are taken from secondary sources describing the notification of 13 November 2025. The dates for the Rules come from Rule 1 itself. The scope of Rule 8(3) is under debate. Confirm these before advising a client.

Sheet Obligations Matrix
A1: Obligations Matrix
A2: One row per legal duty. Fill in the yellow columns. Use the filters on 'Area' or 'Applies to'.
A4: Control identifier | B4: Area | C4: Requirement in plain English | D4: Main legal provision | E4: Provisions covered in this row | F4: Other related provisions (other rows to read) | G4: Exact legal text | H4: ISO/IEC 27001:2022 Annex A reference (our own description) | I4: Applies to | J4: Trigger or event | K4: Time limit | L4: In force from | M4: Maximum penalty | N4: Action for the governance, risk and compliance team | O4: Action for engineering | P4: Evidence to keep | Q4: Risk weight (1 to 3) | R4: Current status | S4: Owner (full name and designation) | T4: Gap notes | U4: Target date | V4: Priority | W4: Days until in force
A5: DPDP-Act-S4 | B5: Lawful basis | C5: Personal data may be processed only for a lawful purpose, and only with the person's consent or for one of the 'certain legitimate uses' listed in Section 7. | D5: Digital Personal Data Protection Act, 2023, Section 4 | E5: Act s.4(1), s.4(2) | F5: DPDP-Act-S6(1); DPDP-Act-S7 | G5: =HYPERLINK("#'Legal Text'!A5","Read the exact text") | H5: Annex A 5.31 (legal and regulatory requirements identified and kept up to date); Annex A 5.34 (privacy and protection of personal information) | I5: All Data Fiduciaries | J5: Any processing of digital personal data | K5: Before processing starts | L5: 46520 | M5: Up to ₹50 crore (Schedule to the Act, item 7: breach of any other provision) | N5: Maintain a register of processing activities. For each activity, record whether it relies on consent or on a named clause of Section 7. | O5: Label every data flow and data store with its purpose and its legal basis. Block new data flows that have no recorded basis. | P5: Approved register of processing activities; inventory of data flows with their labels. | Q5: 3 | R5: Not assessed | V5: =IF(OR(R5="In place",R5="Not applicable to this organisation"),"Closed",IF(Q5=3,"Priority 1",IF(Q5=2,"Priority 2","Priority 3"))) | W5: =IF(L5="","",MAX(0,L5-TODAY()))
A6: DPDP-Act-S7 | B6: Lawful basis | C6: Processing without consent is allowed only for the uses listed in Section 7, for example data the person gave voluntarily for a stated purpose, legal obligations, court orders, medical emergencies, disasters, and employment purposes. | D6: Digital Personal Data Protection Act, 2023, Section 7 | E6: Act s.7(a) to s.7(i) | F6: DPDP-Act-S4 | G6: =HYPERLINK("#'Legal Text'!A6","Read the exact text") | H6: Annex A 5.31 (legal and regulatory requirements); Annex A 5.34 (privacy and protection of personal information) | I6: All Data Fiduciaries | J6: Relying on a ground other than consent | K6: Before processing starts | L6: 46520 | M6: Up to ₹50 crore (Schedule to the Act, item 7: breach of any other provision) | N6: Write a short justification for each processing activity that relies on Section 7, naming the clause. Review the justifications every year. | O6: Record the Section 7 clause in the same labels used for the purpose and legal basis. | P6: One justification note per processing activity. | Q6: 2 | R6: Not assessed | V6: =IF(OR(R6="In place",R6="Not applicable to this organisation"),"Closed",IF(Q6=3,"Priority 1",IF(Q6=2,"Priority 2","Priority 3"))) | W6: =IF(L6="","",MAX(0,L6-TODAY()))
A7: DPDP-Act-S5(1) | B7: Notice | C7: Every request for consent must come with, or after, a notice that lists the personal data, the purpose, the goods or services it enables, and how to withdraw consent, exercise rights and complain to the Data Protection Board. The notice must stand on its own and be in clear, plain language, in English or a language in the Eighth Schedule to the Constitution. | D7: Digital Personal Data Protection Act, 2023, Section 5(1) | E7: Act s.5(1), s.5(3), s.6(3); Rules 3(a), 3(b), 3(c) | F7: DPDP-Act-S6(4) (withdrawal route in the notice, Rule 3(c)(i)) | G7: =HYPERLINK("#'Legal Text'!A7","Read the exact text") | H7: Annex A 5.34 (privacy and protection of personal information) | I7: All Data Fiduciaries | J7: Every request for consent | K7: With or before the request | L7: 46520 | M7: Up to ₹50 crore (Schedule to the Act, item 7: breach of any other provision) | N7: Have legal approve the notice text and each language version. Keep every version under version control. | O7: Show the notice before the consent screen. Record which notice version each person saw. | P7: All notice versions; screenshots of each consent journey; record of the notice version shown to each person. | Q7: 3 | R7: Not assessed | V7: =IF(OR(R7="In place",R7="Not applicable to this organisation"),"Closed",IF(Q7=3,"Priority 1",IF(Q7=2,"Priority 2","Priority 3"))) | W7: =IF(L7="","",MAX(0,L7-TODAY()))
A8: DPDP-Act-S5(2) | B8: Notice | C8: Where consent was given before the Act came into force, send each person a notice describing the data, the purpose and their rights as soon as reasonably practicable. Processing may continue until the person withdraws consent. | D8: Digital Personal Data Protection Act, 2023, Section 5(2) | E8: Act s.5(2)(a), s.5(2)(b) | F8: DPDP-Act-S5(1) | G8: =HYPERLINK("#'Legal Text'!A9","Read the exact text") | H8: Annex A 5.34 (privacy and protection of personal information) | I8: All Data Fiduciaries holding consent given before commencement | J8: Commencement of the Act's obligations | K8: As soon as reasonably practicable | L8: 46520 | M8: Up to ₹50 crore (Schedule to the Act, item 7: breach of any other provision) | N8: Identify the people covered and fix the date of the notice campaign. | O8: Send the notice by email or in the app; record delivery and failed deliveries. | P8: Campaign record; delivery logs. | Q8: 2 | R8: Not assessed | V8: =IF(OR(R8="In place",R8="Not applicable to this organisation"),"Closed",IF(Q8=3,"Priority 1",IF(Q8=2,"Priority 2","Priority 3"))) | W8: =IF(L8="","",MAX(0,L8-TODAY()))
A9: DPDP-Act-S6(1) | B9: Consent | C9: Consent must be free, specific, informed, unconditional and unambiguous, given by a clear positive action, and limited to the data needed for the stated purpose. Any part of a consent that breaks the law is invalid to that extent. | D9: Digital Personal Data Protection Act, 2023, Section 6(1) | E9: Act s.6(1), s.6(2) | F9: DPDP-Act-S5(1) (s.6(3), request in plain language) | G9: =HYPERLINK("#'Legal Text'!A10","Read the exact text") | H9: Annex A 5.34 (privacy and protection of personal information) | I9: All Data Fiduciaries | J9: Every request for consent | K9: At the time of collection | L9: 46520 | M9: Up to ₹50 crore (Schedule to the Act, item 7: breach of any other provision) | N9: Review every consent journey for bundled consents and for data that is not needed. | O9: No pre-ticked boxes. A separate choice for each purpose. Collect only the fields mapped to a purpose. | P9: Review report of consent screens; inventory of consent screens. | Q9: 3 | R9: Not assessed | V9: =IF(OR(R9="In place",R9="Not applicable to this organisation"),"Closed",IF(Q9=3,"Priority 1",IF(Q9=2,"Priority 2","Priority 3"))) | W9: =IF(L9="","",MAX(0,L9-TODAY()))
A10: DPDP-Act-S6(4) | B10: Consent | C10: Withdrawing consent must be as easy as giving it. After withdrawal, the Data Fiduciary must stop processing within a reasonable time and make its Data Processors stop, unless the law requires or authorises the processing. | D10: Digital Personal Data Protection Act, 2023, Section 6(4) | E10: Act s.6(4), s.6(5), s.6(6) | F10: DPDP-Act-S5(1); DPDP-Act-S8(7) | G10: =HYPERLINK("#'Legal Text'!A11","Read the exact text") | H10: Annex A 5.34 (privacy and protection of personal information) | I10: All Data Fiduciaries | J10: Consent is withdrawn | K10: Within a reasonable time (the Act does not set a number of days) | L10: 46520 | M10: Up to ₹50 crore (Schedule to the Act, item 7: breach of any other provision) | N10: Set an internal time limit for 'a reasonable time'. Include every Data Processor in the procedure. | O10: One-step withdrawal. The withdrawal is sent automatically to every system and every Data Processor, and each confirmation is recorded. | P10: Report of withdrawals against the internal time limit; confirmations from Data Processors. | Q10: 3 | R10: Not assessed | V10: =IF(OR(R10="In place",R10="Not applicable to this organisation"),"Closed",IF(Q10=3,"Priority 1",IF(Q10=2,"Priority 2","Priority 3"))) | W10: =IF(L10="","",MAX(0,L10-TODAY()))
A11: DPDP-Act-S6(10) | B11: Consent | C11: If a question arises in a proceeding, the Data Fiduciary must be able to prove that the notice was given and that consent was obtained in line with the Act and the Rules. | D11: Digital Personal Data Protection Act, 2023, Section 6(10) | E11: Act s.6(10) | F11: DPDP-Act-S5(1) | G11: =HYPERLINK("#'Legal Text'!A12","Read the exact text") | H11: Annex A 5.33 (protection of records); Annex A 5.34 (privacy and protection of personal information) | I11: All Data Fiduciaries | J11: A dispute or a proceeding before the Data Protection Board | K11: When asked | L11: 46520 | M11: Up to ₹50 crore (Schedule to the Act, item 7: breach of any other provision) | N11: Define what counts as proof of consent and how long consent records are kept. | O11: A tamper-evident consent record: who consented, to what, when, through which channel, and the notice version shown. | P11: Sample consent records retrieved by customer identifier. | Q11: 3 | R11: Not assessed | V11: =IF(OR(R11="In place",R11="Not applicable to this organisation"),"Closed",IF(Q11=3,"Priority 1",IF(Q11=2,"Priority 2","Priority 3"))) | W11: =IF(L11="","",MAX(0,L11-TODAY()))
A12: DPDP-Rule-4(1) | B12: Consent | C12: Consent Managers must be companies incorporated in India and registered with the Data Protection Board. A Data Fiduciary may allow people to give, review and withdraw consent through a registered Consent Manager. | D12: Digital Personal Data Protection Rules, 2025, Rule 4(1) | E12: Act s.6(7), s.6(8), s.6(9); Rules 4(1) to 4(6); First Schedule, Parts A and B | F12: DPDP-Act-S6(4) | G12: =HYPERLINK("#'Legal Text'!A13","Read the exact text") | H12: Annex A 5.19 and 5.20 (managing suppliers and agreeing security requirements with them); Annex A 5.34 (privacy and protection of personal information) | I12: Consent Managers; Data Fiduciaries that choose to use one | J12: Decision to use a Consent Manager | K12: Registration opens when Rule 4 comes into force | L12: 46339 | M12: Up to ₹50 crore (Schedule to the Act, item 7: breach of any other provision) | N12: Decide whether to use a Consent Manager. Confirm the chosen provider's registration with the Board. | O12: Integrate with the Consent Manager's interface and use its consent records when deciding what processing is allowed. | P12: Decision note; integration test records. | Q12: 1 | R12: Not assessed | V12: =IF(OR(R12="In place",R12="Not applicable to this organisation"),"Closed",IF(Q12=3,"Priority 1",IF(Q12=2,"Priority 2","Priority 3"))) | W12: =IF(L12="","",MAX(0,L12-TODAY()))
A13: DPDP-Act-S8(1) | B13: Accountability | C13: The Data Fiduciary remains responsible for compliance even for processing done on its behalf by Data Processors. It may use a Data Processor only under a valid contract. | D13: Digital Personal Data Protection Act, 2023, Section 8(1) | E13: Act s.8(1), s.8(2) | F13: DPDP-Rule-6(1)(f) (security terms in processor contracts) | G13: =HYPERLINK("#'Legal Text'!A15","Read the exact text") | H13: Annex A 5.19 to 5.23 (supplier relationships, supplier agreements, the technology supply chain, monitoring of suppliers, and use of cloud services) | I13: All Data Fiduciaries | J13: Engaging a Data Processor | K13: Before the engagement starts | L13: 46520 | M13: Up to ₹50 crore (Schedule to the Act, item 7: breach of any other provision) | N13: Keep a register of every vendor that receives personal data. Use standard contract clauses covering security, erasure and breach notification. | O13: Inventory of every vendor receiving personal data, including software-as-a-service tools. | P13: Signed contracts; vendor register. | Q13: 3 | R13: Not assessed | V13: =IF(OR(R13="In place",R13="Not applicable to this organisation"),"Closed",IF(Q13=3,"Priority 1",IF(Q13=2,"Priority 2","Priority 3"))) | W13: =IF(L13="","",MAX(0,L13-TODAY()))
A14: DPDP-Act-S8(3) | B14: Accountability | C14: Where personal data is likely to be used for a decision about the person, or disclosed to another Data Fiduciary, it must be complete, accurate and consistent. | D14: Digital Personal Data Protection Act, 2023, Section 8(3) | E14: Act s.8(3)(a), s.8(3)(b) | F14: None | G14: =HYPERLINK("#'Legal Text'!A16","Read the exact text") | H14: Annex A 5.34 (privacy and protection of personal information) | I14: All Data Fiduciaries | J14: Decisions about a person, or disclosure to another Data Fiduciary | K14: Ongoing | L14: 46520 | M14: Up to ₹50 crore (Schedule to the Act, item 7: breach of any other provision) | N14: Identify processing used for decisions; assign an owner for data quality. | O14: Validation rules; corrections applied to every copy of the record. | P14: Data-quality check results; correction logs. | Q14: 1 | R14: Not assessed | V14: =IF(OR(R14="In place",R14="Not applicable to this organisation"),"Closed",IF(Q14=3,"Priority 1",IF(Q14=2,"Priority 2","Priority 3"))) | W14: =IF(L14="","",MAX(0,L14-TODAY()))
A15: DPDP-Act-S38 | B15: Accountability | C15: The Act applies in addition to other laws. Where it conflicts with another law, the Act prevails to the extent of the conflict. | D15: Digital Personal Data Protection Act, 2023, Section 38 | E15: Act s.38(1), s.38(2) | F15: DPDP-Act-S8(7); DPDP-Rule-8(3); DPDP-Act-S16 | G15: =HYPERLINK("#'Legal Text'!A17","Read the exact text") | H15: Annex A 5.31 (legal, statutory, regulatory and contractual requirements) | I15: All Data Fiduciaries | J15: A DPDP duty differs from a sector rule (for example RBI retention or storage rules) | K15: Before the affected processing. Commencement date of s.38 to be confirmed from the notification | M15: No separate penalty | N15: Keep a register of conflicts between DPDP and sector rules, with the decision taken and the legal reasoning for each. | O15: Apply each recorded decision through configuration (for example a retention period), not by changing code. | P15: Conflict register with decisions and approvals. | Q15: 2 | R15: Not assessed | V15: =IF(OR(R15="In place",R15="Not applicable to this organisation"),"Closed",IF(Q15=3,"Priority 1",IF(Q15=2,"Priority 2","Priority 3"))) | W15: =IF(L15="","",MAX(0,L15-TODAY()))
A16: DPDP-Act-S44(2) | B16: Accountability | C16: Section 43A of the Information Technology Act, 2000 (compensation for failure to protect sensitive personal data) and the related rule-making power in Section 87(2)(ob) are omitted. Policies, notices and contracts built on that earlier regime need to move to the DPDP Act. | D16: Digital Personal Data Protection Act, 2023, Section 44(2) | E16: Act s.44(2)(a) to (c) | F16: None | G16: =HYPERLINK("#'Legal Text'!A18","Read the exact text") | H16: Annex A 5.31 (legal and regulatory requirements); 5.1 (policies for information security) | I16: All companies that relied on the IT Act regime | J16: Commencement of s.44(2) | K16: By commencement. Date of s.44(2) to be confirmed from the notification | M16: No separate penalty | N16: Find every policy, privacy notice and contract that cites Section 43A of the IT Act or the 2011 rules made under it, and update them to the DPDP Act. | O16: None directly. | P16: List of documents reviewed and updated. | Q16: 1 | R16: Not assessed | V16: =IF(OR(R16="In place",R16="Not applicable to this organisation"),"Closed",IF(Q16=3,"Priority 1",IF(Q16=2,"Priority 2","Priority 3"))) | W16: =IF(L16="","",MAX(0,L16-TODAY()))
A17: DPDP-Act-S8(5) | B17: Security | C17: Protect personal data with reasonable security safeguards to prevent a breach. At a minimum: encryption, masking or tokenisation; access control; logs, monitoring and review; backups for continuity; keeping logs and personal data for one year for detection and investigation; security clauses in Data Processor contracts; and technical and organisational measures. | D17: Digital Personal Data Protection Act, 2023, Section 8(5) | E17: Act s.8(4), s.8(5); Rules 6(2). Each clause of Rule 6(1) has its own row. | F17: DPDP-Rule-6(1)(a) to DPDP-Rule-6(1)(g); DPDP-Rule-7(1); DPDP-Rule-8(3) | G17: =HYPERLINK("#'Legal Text'!A19","Read the exact text") | H17: Annex A 8.24 (use of cryptography); 8.11 (data masking); 5.15 and 8.3 (access control and restriction of access); 8.2 (privileged access); 8.15 (logging); 8.16 (monitoring); 8.13 (information backup); 5.20 (security requirements in supplier agreements) | I17: All Data Fiduciaries, including processing done by their Data Processors | J17: Always | K17: Continuous | L17: 46520 | M17: Up to ₹250 crore (Schedule to the Act, item 1: Section 8(5)) | N17: This row is the overall duty. Assess and test each clause of Rule 6(1) in its own row below. | O17: Encryption at rest and in transit; access reviews; central logging kept for at least one year; backup and restore tests. | P17: Configuration exports; access review records; log retention settings; restore test reports. | Q17: 3 | R17: Not assessed | V17: =IF(OR(R17="In place",R17="Not applicable to this organisation"),"Closed",IF(Q17=3,"Priority 1",IF(Q17=2,"Priority 2","Priority 3"))) | W17: =IF(L17="","",MAX(0,L17-TODAY()))
A18: DPDP-Rule-6(1)(a) | B18: Security | C18: Secure personal data through encryption, obfuscation, masking or virtual tokens mapped to the data. | D18: Digital Personal Data Protection Rules, 2025, Rule 6(1)(a) | E18: Rules 6(1)(a) | F18: DPDP-Act-S8(5) (overall duty) | G18: =HYPERLINK("#'Legal Text'!A20","Read the exact text") | H18: Annex A 8.24 (use of cryptography); 8.11 (data masking) | I18: All Data Fiduciaries, including processing done by their Data Processors | J18: Always | K18: Continuous | L18: 46520 | M18: Up to ₹250 crore (Schedule to the Act, item 1: part of the Section 8(5) duty) | N18: Approve an encryption and key management standard, including where masking or tokens must be used. | O18: Encryption at rest and in transit for every store holding personal data, checked before each release. Masked or tokenised data outside production. | P18: Pre-release check results; encryption configuration report. | Q18: 3 | R18: Not assessed | V18: =IF(OR(R18="In place",R18="Not applicable to this organisation"),"Closed",IF(Q18=3,"Priority 1",IF(Q18=2,"Priority 2","Priority 3"))) | W18: =IF(L18="","",MAX(0,L18-TODAY()))
A19: DPDP-Rule-6(1)(b) | B19: Security | C19: Control access to the computer resources used by the Data Fiduciary and its Data Processors. | D19: Digital Personal Data Protection Rules, 2025, Rule 6(1)(b) | E19: Rules 6(1)(b) | F19: DPDP-Act-S8(5) (overall duty) | G19: =HYPERLINK("#'Legal Text'!A21","Read the exact text") | H19: Annex A 5.15 (access control); 5.18 (access rights); 8.2 (privileged access); 8.5 (secure authentication) | I19: All Data Fiduciaries, including processing done by their Data Processors | J19: Always | K19: Continuous | L19: 46520 | M19: Up to ₹250 crore (Schedule to the Act, item 1: part of the Section 8(5) duty) | N19: Access control policy; periodic access reviews with named reviewers. | O19: Single sign-on with multi-factor authentication; no long-lived access keys; least-privilege roles. | P19: List of users and keys showing none stored; access review records. | Q19: 3 | R19: Not assessed | V19: =IF(OR(R19="In place",R19="Not applicable to this organisation"),"Closed",IF(Q19=3,"Priority 1",IF(Q19=2,"Priority 2","Priority 3"))) | W19: =IF(L19="","",MAX(0,L19-TODAY()))
A20: DPDP-Rule-6(1)(c) | B20: Security | C20: Keep logs of access to personal data, and monitor and review them, so that unauthorised access can be detected, investigated and stopped from recurring. | D20: Digital Personal Data Protection Rules, 2025, Rule 6(1)(c) | E20: Rules 6(1)(c) | F20: DPDP-Act-S8(5) (overall duty) | G20: =HYPERLINK("#'Legal Text'!A22","Read the exact text") | H20: Annex A 8.15 (logging); 8.16 (monitoring activities) | I20: All Data Fiduciaries, including processing done by their Data Processors | J20: Always | K20: Continuous | L20: 46520 | M20: Up to ₹250 crore (Schedule to the Act, item 1: part of the Section 8(5) duty) | N20: Define which events are logged, who reviews them and how often. | O20: An audit trail that cannot be stopped or altered; access logging on data stores; alerts on suspicious access. | P20: Audit trail configuration; test results; review records. | Q20: 3 | R20: Not assessed | V20: =IF(OR(R20="In place",R20="Not applicable to this organisation"),"Closed",IF(Q20=3,"Priority 1",IF(Q20=2,"Priority 2","Priority 3"))) | W20: =IF(L20="","",MAX(0,L20-TODAY()))
A21: DPDP-Rule-6(1)(d) | B21: Security | C21: Take reasonable measures, such as backups, so that processing can continue if personal data is destroyed, lost or compromised. | D21: Digital Personal Data Protection Rules, 2025, Rule 6(1)(d) | E21: Rules 6(1)(d) | F21: DPDP-Act-S8(5) (overall duty) | G21: =HYPERLINK("#'Legal Text'!A23","Read the exact text") | H21: Annex A 8.13 (information backup); 8.14 (redundancy); 5.30 (ICT readiness for business continuity) | I21: All Data Fiduciaries, including processing done by their Data Processors | J21: Always | K21: Continuous | L21: 46520 | M21: Up to ₹250 crore (Schedule to the Act, item 1: part of the Section 8(5) duty) | N21: Backup policy with recovery objectives for each system holding personal data. | O21: Automated backups; regular restore tests with recorded results. | P21: Backup reports; restore test results. | Q21: 2 | R21: Not assessed | V21: =IF(OR(R21="In place",R21="Not applicable to this organisation"),"Closed",IF(Q21=3,"Priority 1",IF(Q21=2,"Priority 2","Priority 3"))) | W21: =IF(L21="","",MAX(0,L21-TODAY()))
A22: DPDP-Rule-6(1)(e) | B22: Security | C22: Keep the logs and personal data needed to detect, investigate and recover from unauthorised access for one year, unless another law requires otherwise. | D22: Digital Personal Data Protection Rules, 2025, Rule 6(1)(e) | E22: Rules 6(1)(e) | F22: DPDP-Act-S8(5) (overall duty) | G22: =HYPERLINK("#'Legal Text'!A24","Read the exact text") | H22: Annex A 8.15 (logging); 5.33 (protection of records) | I22: All Data Fiduciaries, including processing done by their Data Processors | J22: Each log entry or record | K22: One year | L22: 46520 | M22: Up to ₹250 crore (Schedule to the Act, item 1: part of the Section 8(5) duty) | N22: Record the retention period for each type of log and the legal reason for any different period. | O22: Log retention of at least 365 days, locked so that it cannot be shortened or deleted early; checked before release. | P22: Retention settings; test results showing logs cannot be deleted early. | Q22: 3 | R22: Partially in place | S22: Example: Head of IT Infrastructure | T22: EXAMPLE ENTRY: application logs are kept for 90 days, but Rule 6(1)(e) requires one year. Logs can be deleted by any administrator. | U22: 46418 | V22: =IF(OR(R22="In place",R22="Not applicable to this organisation"),"Closed",IF(Q22=3,"Priority 1",IF(Q22=2,"Priority 2","Priority 3"))) | W22: =IF(L22="","",MAX(0,L22-TODAY()))
A23: DPDP-Rule-6(1)(f) | B23: Security | C23: Include terms in each contract with a Data Processor requiring it to take reasonable security safeguards. | D23: Digital Personal Data Protection Rules, 2025, Rule 6(1)(f) | E23: Rules 6(1)(f) | F23: DPDP-Act-S8(5) (overall duty) | G23: =HYPERLINK("#'Legal Text'!A25","Read the exact text") | H23: Annex A 5.19 (supplier relationships); 5.20 (security in supplier agreements) | I23: All Data Fiduciaries, including processing done by their Data Processors | J23: Before engaging a Data Processor | K23: Before data is shared | L23: 46520 | M23: Up to ₹250 crore (Schedule to the Act, item 1: part of the Section 8(5) duty) | N23: Standard contract clauses; register of Data Processors with the clause reference for each. | O23: Vendor register linked to the data flows each vendor receives. | P23: Signed contracts; vendor register. | Q23: 2 | R23: Not assessed | V23: =IF(OR(R23="In place",R23="Not applicable to this organisation"),"Closed",IF(Q23=3,"Priority 1",IF(Q23=2,"Priority 2","Priority 3"))) | W23: =IF(L23="","",MAX(0,L23-TODAY()))
A24: DPDP-Rule-6(1)(g) | B24: Security | C24: Take appropriate technical and organisational measures to make sure the safeguards actually work. | D24: Digital Personal Data Protection Rules, 2025, Rule 6(1)(g) | E24: Rules 6(1)(g) | F24: DPDP-Act-S8(5) (overall duty) | G24: =HYPERLINK("#'Legal Text'!A26","Read the exact text") | H24: Annex A 5.1 (policies); 5.35 (independent review); 5.36 (compliance with policies and standards) | I24: All Data Fiduciaries, including processing done by their Data Processors | J24: Always | K24: Continuous | L24: 46520 | M24: Up to ₹250 crore (Schedule to the Act, item 1: part of the Section 8(5) duty) | N24: Assign an owner to each safeguard; review results regularly with management. | O24: Automated tests of each control; results stored where they cannot be altered. | P24: Control test results; management review records. | Q24: 3 | R24: Not assessed | V24: =IF(OR(R24="In place",R24="Not applicable to this organisation"),"Closed",IF(Q24=3,"Priority 1",IF(Q24=2,"Priority 2","Priority 3"))) | W24: =IF(L24="","",MAX(0,L24-TODAY()))
A25: DPDP-Rule-7(1) | B25: Breach | C25: On becoming aware of a personal data breach, inform each affected person without delay: what happened, the likely consequences for them, what is being done, what they can do, and whom to contact. | D25: Digital Personal Data Protection Rules, 2025, Rule 7(1) | E25: Act s.8(6) (intimation to each affected person); Rules 7(1)(a) to 7(1)(e) | F25: DPDP-Rule-7(2) | G25: =HYPERLINK("#'Legal Text'!A27","Read the exact text") | H25: Annex A 5.24 to 5.26 (incident planning, assessment and response); 5.28 (collection of evidence) | I25: All Data Fiduciaries | J25: Becoming aware of a personal data breach | K25: Without delay | L25: 46520 | M25: Up to ₹200 crore (Schedule to the Act, item 2: Section 8(6)) | N25: Breach procedure; pre-approved message templates; a record of every decision with its time. | O25: Ability to identify affected people in each system; bulk notification through the user account or registered contact details. | P25: Notification records; decision record with times. | Q25: 3 | R25: Not assessed | V25: =IF(OR(R25="In place",R25="Not applicable to this organisation"),"Closed",IF(Q25=3,"Priority 1",IF(Q25=2,"Priority 2","Priority 3"))) | W25: =IF(L25="","",MAX(0,L25-TODAY()))
A26: DPDP-Rule-7(2) | B26: Breach | C26: Inform the Data Protection Board without delay with an initial description, and within 72 hours with a detailed report: updated description, facts and causes, mitigation, findings on who caused it, measures to prevent recurrence, and a report on the notices sent to affected people. A longer period applies only if the Board allows it on a written request. | D26: Digital Personal Data Protection Rules, 2025, Rule 7(2) | E26: Act s.8(6) (intimation to the Board); Rules 7(2)(a), 7(2)(b) | F26: DPDP-Rule-7(1) | G26: =HYPERLINK("#'Legal Text'!A29","Read the exact text") | H26: Annex A 5.5 (contact with authorities); 5.24 to 5.26 (incident planning, assessment and response) | I26: All Data Fiduciaries | J26: Becoming aware of a personal data breach | K26: Without delay, then a detailed report within 72 hours | L26: 46520 | M26: Up to ₹200 crore (Schedule to the Act, item 2: Section 8(6)) | N26: 72-hour report template; a named approver; a template for requesting more time. | O26: Forensic logging and timeline reconstruction to complete the 72-hour report. | P26: Submissions to the Board; incident timeline. | Q26: 3 | R26: Not assessed | V26: =IF(OR(R26="In place",R26="Not applicable to this organisation"),"Closed",IF(Q26=3,"Priority 1",IF(Q26=2,"Priority 2","Priority 3"))) | W26: =IF(L26="","",MAX(0,L26-TODAY()))
A27: DPDP-Act-S8(7) | B27: Retention and erasure | C27: Erase personal data when consent is withdrawn or when the purpose is no longer being served, whichever is earlier, and make Data Processors erase it too, unless the law requires it to be kept. | D27: Digital Personal Data Protection Act, 2023, Section 8(7) | E27: Act s.8(7)(a), s.8(7)(b) | F27: DPDP-Rule-8(3); DPDP-Rule-8(1); DPDP-Act-S12; DPDP-Act-S38 | G27: =HYPERLINK("#'Legal Text'!A30","Read the exact text") | H27: Annex A 8.10 (deleting information when no longer required); 5.34 (privacy and protection of personal information) | I27: All Data Fiduciaries | J27: Withdrawal of consent, or the purpose is no longer served | K27: When the trigger occurs | L27: 46520 | M27: Up to ₹50 crore (Schedule to the Act, item 7: breach of any other provision) | N27: Retention schedule for each category of data, stating the legal reason for any retention. | O27: Three states for every record: in use, sealed (kept only for a legal reason, restricted, every read logged), erased. Each record has its own expiry date. Erasure reaches logs and Data Processors. Backups are kept for weeks, not years, never edited and used only for recovery; any restore goes to a new copy, and the erasure register is re-applied before the data is used. | P27: Erasure job records; search results for a deleted test customer after 1 day, 30 days and 1 year, and after a backup restore. | Q27: 3 | R27: Not assessed | V27: =IF(OR(R27="In place",R27="Not applicable to this organisation"),"Closed",IF(Q27=3,"Priority 1",IF(Q27=2,"Priority 2","Priority 3"))) | W27: =IF(L27="","",MAX(0,L27-TODAY()))
A28: DPDP-Rule-8(3) | B28: Retention and erasure | C28: Keep personal data, related traffic data and processing logs for at least one year from the date of each processing, including data held by Data Processors, for the purposes in the Seventh Schedule; then erase them unless another law requires longer. The Rule's illustration says this applies even if the person deletes her account. | D28: Digital Personal Data Protection Rules, 2025, Rule 8(3) | E28: Rules 8(3); Seventh Schedule | F28: DPDP-Rule-6(1)(e); DPDP-Rule-23 | G28: =HYPERLINK("#'Legal Text'!A31","Read the exact text") | H28: Annex A 5.33 (protection of records); 8.15 (logging) | I28: All Data Fiduciaries (the scope of this rule is under debate) | J28: Each processing event | K28: At least one year from each processing event, then erase | L28: 46520 | M28: Up to ₹50 crore (Schedule to the Act, item 7: breach of any other provision) | N28: Record the legal reason for retention for each data category. Track any clarification from the Ministry on the scope of this rule. | O28: Retention periods held as configuration, not written into code. A sealed store with restricted access. An expiry date for each processing event. | P28: Retention configuration; access logs of the sealed store. | Q28: 3 | R28: Not assessed | V28: =IF(OR(R28="In place",R28="Not applicable to this organisation"),"Closed",IF(Q28=3,"Priority 1",IF(Q28=2,"Priority 2","Priority 3"))) | W28: =IF(L28="","",MAX(0,L28-TODAY()))
A29: DPDP-Rule-8(1) | B29: Retention and erasure | C29: Applies only to large platforms: erase personal data after three years without contact from the person (counted from her last contact or the commencement of the Rules, whichever is later), except for access to her account and stored-value tokens. Tell the person at least 48 hours before erasure. | D29: Digital Personal Data Protection Rules, 2025, Rule 8(1) | E29: Act s.8(8), s.8(11); Rules 8(1), 8(2); Third Schedule | F29: DPDP-Act-S8(7) | G29: =HYPERLINK("#'Legal Text'!A32","Read the exact text") | H29: Annex A 8.10 (deleting information when no longer required) | I29: E-commerce entities with 2 crore or more registered users in India; online gaming intermediaries with 50 lakh or more; social media intermediaries with 2 crore or more | J29: The person has not been in contact | K29: Three years; notice at least 48 hours before erasure | L29: 46520 | M29: Up to ₹50 crore (Schedule to the Act, item 7: breach of any other provision) | N29: Confirm whether the organisation crosses a Third Schedule threshold. | O29: Update the last-contact date on every login or contact. Send the notice 48 hours before. The erasure job checks the last-contact date again at the moment it runs. | P29: Notice records; erasure records. | Q29: 2 | R29: Not assessed | V29: =IF(OR(R29="In place",R29="Not applicable to this organisation"),"Closed",IF(Q29=3,"Priority 1",IF(Q29=2,"Priority 2","Priority 3"))) | W29: =IF(L29="","",MAX(0,L29-TODAY()))
A30: DPDP-Rule-9 | B30: Rights and grievances | C30: Publish, prominently on the website or app, the business contact details of the Data Protection Officer or of a person who can answer questions about processing. Include these details in every reply to a request to exercise rights. | D30: Digital Personal Data Protection Rules, 2025, Rule 9 | E30: Act s.8(9); Rules 9 | F30: DPDP-Act-S5(1) | G30: =HYPERLINK("#'Legal Text'!A35","Read the exact text") | H30: Annex A 5.34 (privacy and protection of personal information) | I30: All Data Fiduciaries | J30: Always, and every reply to a rights request | K30: Ongoing | L30: 46520 | M30: Up to ₹50 crore (Schedule to the Act, item 7: breach of any other provision) | N30: Name the contact person. Put the details into every reply template. | O30: Contact details in the website and app footer and in every reply template. | P30: Screenshots; copies of reply templates. | Q30: 2 | R30: Not assessed | V30: =IF(OR(R30="In place",R30="Not applicable to this organisation"),"Closed",IF(Q30=3,"Priority 1",IF(Q30=2,"Priority 2","Priority 3"))) | W30: =IF(L30="","",MAX(0,L30-TODAY()))
A31: DPDP-Act-S11(1) | B31: Rights and grievances | C31: On request, give the person a summary of the personal data being processed and the processing done, and the identities of other Data Fiduciaries and Data Processors it has been shared with. | D31: Digital Personal Data Protection Act, 2023, Section 11(1) | E31: Act s.11(1)(a) to (c), s.11(2); Rules 14(1), 14(2), 14(5) | F31: DPDP-Act-S12; DPDP-Act-S13 | G31: =HYPERLINK("#'Legal Text'!A37","Read the exact text") | H31: Annex A 5.34 (privacy and protection of personal information) | I31: All Data Fiduciaries | J31: Request for access | K31: The Rules set no specific period; grievances must be answered within the published period of not more than 90 days | L31: 46520 | M31: Up to ₹50 crore (Schedule to the Act, item 7: breach of any other provision) | N31: Set an internal time limit and an identity check procedure. | O31: A map of each person's data across systems to produce the summary; a register of sharing. | P31: Request log with dates and replies. | Q31: 3 | R31: Not assessed | V31: =IF(OR(R31="In place",R31="Not applicable to this organisation"),"Closed",IF(Q31=3,"Priority 1",IF(Q31=2,"Priority 2","Priority 3"))) | W31: =IF(L31="","",MAX(0,L31-TODAY()))
A32: DPDP-Act-S12 | B32: Rights and grievances | C32: The person may ask for correction, completion, updating and erasure. On an erasure request, erase her data unless it is needed for the specified purpose or to comply with the law. | D32: Digital Personal Data Protection Act, 2023, Section 12(1) to 12(3) | E32: Act s.12(1), s.12(2)(a) to (c), s.12(3) | F32: DPDP-Act-S11(1); DPDP-Act-S8(7) | G32: =HYPERLINK("#'Legal Text'!A40","Read the exact text") | H32: Annex A 8.10 (deleting information when no longer required); 5.34 (privacy and protection of personal information) | I32: All Data Fiduciaries | J32: Request for correction or erasure | K32: The Rules set no specific period; grievances must be answered within the published period of not more than 90 days | L32: 46520 | M32: Up to ₹50 crore (Schedule to the Act, item 7: breach of any other provision) | N32: Decision rules for when retention overrides erasure, with the legal reason recorded. | O32: Erasure workflow reaching every copy. Reply to the customer stating what is erased, what is kept, why and until when (recommended practice), generated from the retention register. | P32: Request log; erasure evidence; copies of replies sent. | Q32: 3 | R32: Not assessed | V32: =IF(OR(R32="In place",R32="Not applicable to this organisation"),"Closed",IF(Q32=3,"Priority 1",IF(Q32=2,"Priority 2","Priority 3"))) | W32: =IF(L32="","",MAX(0,L32-TODAY()))
A33: DPDP-Act-S13 | B33: Rights and grievances | C33: Provide an effective way to raise grievances and reply within the period published on the website or app, which must not exceed 90 days. The person must use this route before going to the Data Protection Board. | D33: Digital Personal Data Protection Act, 2023, Section 13 | E33: Act s.8(10), s.13(1) to s.13(3); Rules 14(3) | F33: DPDP-Act-S11(1) | G33: =HYPERLINK("#'Legal Text'!A42","Read the exact text") | H33: Annex A 5.34 (privacy and protection of personal information) | I33: All Data Fiduciaries; Consent Managers | J33: Grievance received | K33: Within the published period, not more than 90 days | L33: 46520 | M33: Up to ₹50 crore (Schedule to the Act, item 7: breach of any other provision) | N33: Grievance procedure; published reply period; escalation route. | O33: Ticketing with time limits and reports of ageing tickets. | P33: Time-limit reports; samples of closed tickets. | Q33: 2 | R33: Not assessed | V33: =IF(OR(R33="In place",R33="Not applicable to this organisation"),"Closed",IF(Q33=3,"Priority 1",IF(Q33=2,"Priority 2","Priority 3"))) | W33: =IF(L33="","",MAX(0,L33-TODAY()))
A34: DPDP-Act-S14(1) | B34: Rights and grievances | C34: The person may nominate another individual to exercise her rights if she dies or becomes incapable. | D34: Digital Personal Data Protection Act, 2023, Section 14(1) | E34: Act s.14(1), s.14(2); Rules 14(4) | F34: DPDP-Act-S11(1) | G34: =HYPERLINK("#'Legal Text'!A45","Read the exact text") | H34: Annex A 5.34 (privacy and protection of personal information) | I34: All Data Fiduciaries | J34: Nomination request | K34: Ongoing | L34: 46520 | M34: Up to ₹50 crore (Schedule to the Act, item 7: breach of any other provision) | N34: Nomination procedure in the terms of service. | O34: Nominee field and a verification step. | P34: Nomination records. | Q34: 1 | R34: Not assessed | V34: =IF(OR(R34="In place",R34="Not applicable to this organisation"),"Closed",IF(Q34=3,"Priority 1",IF(Q34=2,"Priority 2","Priority 3"))) | W34: =IF(L34="","",MAX(0,L34-TODAY()))
A35: DPDP-Act-S9(1) | B35: Children and lawful guardians | C35: Before processing any personal data of a child (under 18), obtain the verifiable consent of a parent, after checking that the parent is an identifiable adult, using the Data Fiduciary's own reliable records or identity and age details or a token from an authorised entity such as DigiLocker. | D35: Digital Personal Data Protection Act, 2023, Section 9(1) | E35: Act s.9(1); Rules 10(1), 10(2) | F35: DPDP-Rule-11(1); DPDP-Act-S9(3) | G35: =HYPERLINK("#'Legal Text'!A46","Read the exact text") | H35: Annex A 5.34 (privacy and protection of personal information) | I35: Data Fiduciaries that process children's personal data | J35: A child's account is created or a child's data is collected | K35: Before processing | L35: 46520 | M35: Up to ₹200 crore (Schedule to the Act, item 3: Section 9) | N35: Age assurance policy; decide which route under Rule 10 applies. | O35: Age check at sign-up; parent verification step; consent record linking the parent and the child. | P35: Verification records. | Q35: 3 | R35: Not assessed | V35: =IF(OR(R35="In place",R35="Not applicable to this organisation"),"Closed",IF(Q35=3,"Priority 1",IF(Q35=2,"Priority 2","Priority 3"))) | W35: =IF(L35="","",MAX(0,L35-TODAY()))
A36: DPDP-Act-S9(3) | B36: Children and lawful guardians | C36: Do not process a child's data in a way likely to harm her well-being. Do not track, behaviourally monitor, or target advertising at children, unless an exemption in the Fourth Schedule applies (for example healthcare, education or safety). | D36: Digital Personal Data Protection Act, 2023, Section 9(3) | E36: Act s.9(2), s.9(3), s.9(4), s.9(5); Rules 12(1) to 12(3); Fourth Schedule, Parts A and B | F36: DPDP-Act-S9(1) | G36: =HYPERLINK("#'Legal Text'!A48","Read the exact text") | H36: Annex A 5.34 (privacy and protection of personal information) | I36: Data Fiduciaries that process children's personal data | J36: Always | K36: Ongoing | L36: 46520 | M36: Up to ₹200 crore (Schedule to the Act, item 3: Section 9) | N36: Document any Fourth Schedule exemption relied on. | O36: Switch off targeted advertising and profiling for child accounts. | P36: Advertising platform settings; exemption note. | Q36: 3 | R36: Not assessed | V36: =IF(OR(R36="In place",R36="Not applicable to this organisation"),"Closed",IF(Q36=3,"Priority 1",IF(Q36=2,"Priority 2","Priority 3"))) | W36: =IF(L36="","",MAX(0,L36-TODAY()))
A37: DPDP-Rule-11(1) | B37: Children and lawful guardians | C37: For a person with disability who has a lawful guardian, verify that the guardian was appointed by a court, a designated authority or a local level committee under the law on guardianship. | D37: Digital Personal Data Protection Rules, 2025, Rule 11(1) | E37: Rules 11(1), 11(2) | F37: DPDP-Act-S9(1) | G37: =HYPERLINK("#'Legal Text'!A50","Read the exact text") | H37: Annex A 5.34 (privacy and protection of personal information) | I37: Data Fiduciaries serving such persons | J37: Consent given by a guardian | K37: Before processing | L37: 46520 | M37: Up to ₹200 crore (Schedule to the Act, item 3: Section 9) | N37: Guardian verification procedure. | O37: Document upload and verification step. | P37: Verification records. | Q37: 2 | R37: Not assessed | V37: =IF(OR(R37="In place",R37="Not applicable to this organisation"),"Closed",IF(Q37=3,"Priority 1",IF(Q37=2,"Priority 2","Priority 3"))) | W37: =IF(L37="","",MAX(0,L37-TODAY()))
A38: DPDP-Act-S10(2) | B38: Significant Data Fiduciary | C38: If notified as a Significant Data Fiduciary: appoint a Data Protection Officer based in India and answerable to the board of directors; appoint an independent data auditor; carry out periodic Data Protection Impact Assessments and audits. | D38: Digital Personal Data Protection Act, 2023, Section 10(2) | E38: Act s.10(1)(a) to (f), s.10(2)(a) to (c) | F38: DPDP-Rule-13 | G38: =HYPERLINK("#'Legal Text'!A51","Read the exact text") | H38: Annex A 5.2 (security roles and responsibilities); 5.35 (independent review of information security); 5.34 (privacy and protection of personal information) | I38: Only Data Fiduciaries notified as Significant Data Fiduciaries | J38: Notification by the Central Government | K38: From notification | L38: 46520 | M38: Up to ₹150 crore (Schedule to the Act, item 4: Section 10) | N38: Watch for notification; plan the Data Protection Officer and auditor appointments in advance. | O38: Impact assessment tooling fed by the data inventory. | P38: Appointment letters; impact assessment reports. | Q38: 2 | R38: Not assessed | V38: =IF(OR(R38="In place",R38="Not applicable to this organisation"),"Closed",IF(Q38=3,"Priority 1",IF(Q38=2,"Priority 2","Priority 3"))) | W38: =IF(L38="","",MAX(0,L38-TODAY()))
A39: DPDP-Rule-13 | B39: Significant Data Fiduciary | C39: If notified: carry out an impact assessment and an audit every twelve months from notification; send significant observations to the Data Protection Board; check that algorithmic software does not put people's rights at risk; keep data specified by the Government inside India. | D39: Digital Personal Data Protection Rules, 2025, Rule 13(1) to 13(4) | E39: Rules 13(1) to 13(5) | F39: DPDP-Act-S10(2) | G39: =HYPERLINK("#'Legal Text'!A52","Read the exact text") | H39: Annex A 5.35 (independent review); 5.23 (use of cloud services); 5.31 (legal and regulatory requirements) | I39: Only Data Fiduciaries notified as Significant Data Fiduciaries | J39: Notification by the Central Government | K39: Every twelve months | L39: 46520 | M39: Up to ₹150 crore (Schedule to the Act, item 4: Section 10) | N39: Annual calendar for the impact assessment and audit; review of algorithmic risk. | O39: Controls that keep Government-specified data in Indian regions. | P39: Audit report; submission to the Board; evidence of data location. | Q39: 2 | R39: Not assessed | V39: =IF(OR(R39="In place",R39="Not applicable to this organisation"),"Closed",IF(Q39=3,"Priority 1",IF(Q39=2,"Priority 2","Priority 3"))) | W39: =IF(L39="","",MAX(0,L39-TODAY()))
A40: DPDP-Act-S16 | B40: Transfer outside India | C40: Transfers outside India are allowed unless the Government restricts a country by notification. Meet any Government requirement on making data available to a foreign State. Stricter sector laws still apply. | D40: Digital Personal Data Protection Act, 2023, Section 16 | E40: Act s.16(1), s.16(2); Rules 15 | F40: DPDP-Act-S38 | G40: =HYPERLINK("#'Legal Text'!A53","Read the exact text") | H40: Annex A 5.14 (information transfer); 5.23 (use of cloud services); 5.31 (legal and regulatory requirements) | I40: All Data Fiduciaries transferring data outside India | J40: Transfer outside India | K40: Before the transfer | L40: 46520 | M40: Up to ₹50 crore (Schedule to the Act, item 7: breach of any other provision) | N40: Register of transfers by country and vendor; check sector rules (for example, the Reserve Bank of India's rules on payment data). | O40: Inventory of the regions where data is stored and processed. | P40: Transfer register; region configuration. | Q40: 2 | R40: Not assessed | V40: =IF(OR(R40="In place",R40="Not applicable to this organisation"),"Closed",IF(Q40=3,"Priority 1",IF(Q40=2,"Priority 2","Priority 3"))) | W40: =IF(L40="","",MAX(0,L40-TODAY()))
A41: DPDP-Rule-23 | B41: Government and Data Protection Board | C41: Provide information that the Government calls for, for the purposes in the Seventh Schedule, within the period given. The Government may direct that the person concerned is not told. | D41: Digital Personal Data Protection Rules, 2025, Rule 23(1) and 23(2) | E41: Act s.36; Rules 23(1) to 23(3); Seventh Schedule | F41: DPDP-Rule-8(3) | G41: =HYPERLINK("#'Legal Text'!A55","Read the exact text") | H41: Annex A 5.5 (contact with authorities); 5.31 (legal and regulatory requirements) | I41: Data Fiduciaries and intermediaries | J41: A request from the Government | K41: Within the period stated in the request | L41: 46520 | M41: Up to ₹50 crore (Schedule to the Act, item 7: breach of any other provision) | N41: Procedure for Government requests, including confidentiality handling. | O41: Ability to retrieve retained data and logs (see DPDP-Rule-8(3)). Block automatic customer notices when a confidentiality direction applies. | P41: Register of requests. | Q41: 1 | R41: Not assessed | V41: =IF(OR(R41="In place",R41="Not applicable to this organisation"),"Closed",IF(Q41=3,"Priority 1",IF(Q41=2,"Priority 2","Priority 3"))) | W41: =IF(L41="","",MAX(0,L41-TODAY()))
...

Sheet Legal Text
A1: Legal Text: provisions reproduced word for word
A2: Reproduced from the Gazette of India for reference. The Act text was transcribed from the scanned Gazette copy; check against the Gazette before quoting.
A4: Control identifier | B4: Provision | C4: Exact text as published | D4: Published in
A5: DPDP-Act-S4 | B5: Digital Personal Data Protection Act, 2023, Section 4 | C5: (1) A person may process the personal data of a Data Principal only in accordance with the provisions of this Act and for a lawful purpose,— (a) for which the Data Principal has given her consent; or (b) for certain legitimate uses. (2) For the purposes of this section, the expression “lawful purpose” means any purpose which is not expressly forbidden by law. | D5: Gazette of India, Extraordinary, Part II, Section 1, No. 25, 11 August 2023
A6: DPDP-Act-S7 | B6: Digital Personal Data Protection Act, 2023, Section 7 (opening words, clause (a) and clause (i); clauses (b) to (h) not reproduced here) | C6: A Data Fiduciary may process personal data of a Data Principal for any of following uses, namely:— (a) for the specified purpose for which the Data Principal has voluntarily provided her personal data to the Data Fiduciary, and in respect of which she has not indicated to the Data Fiduciary that she does not consent to the use of her personal data; [clauses (b) to (h) not reproduced here] (i) for the purposes of employment or those related to safeguarding the employer from loss or liability, such as prevention of corporate espionage, maintenance of confidentiality of trade secrets, intellectual property, classified information or provision of any service or benefit sought by a Data Principal who is an employee. | D6: Gazette of India, Extraordinary, Part II, Section 1, No. 25, 11 August 2023
A7: DPDP-Act-S5(1) | B7: Digital Personal Data Protection Act, 2023, Section 5(1) | C7: (1) Every request made to a Data Principal under section 6 for consent shall be accompanied or preceded by a notice given by the Data Fiduciary to the Data Principal, informing her,— (i) the personal data and the purpose for which the same is proposed to be processed; (ii) the manner in which she may exercise her rights under sub-section (4) of section 6 and section 13; and (iii) the manner in which the Data Principal may make a complaint to the Board, in such manner and as may be prescribed. | D7: Gazette of India, Extraordinary, Part II, Section 1, No. 25, 11 August 2023
A8: DPDP-Act-S5(1) | B8: Digital Personal Data Protection Rules, 2025, Rule 3 | C8: 3. Notice given by Data Fiduciary to Data Principal. —The notice given by the Data Fiduciary to the Data Principal shall— (a) be presented and be understandable independently of any other information that has been, is or may be made available by such Data Fiduciary; (b) give, in clear and plain language, a fair account of the details necessary to enable the Data Principal to give specific and informed consent for the processing of her personal data, which shall include, at the minimum, — (i) an itemised description of such personal data; and (ii) the specified purpose or purposes of, and specific description of the goods or services to be provided or uses to be enabled by, such processing; and (c) give, the particular communication link for accessing the website or app, or both, of such Data Fiduciary, and a description of other means, if any, using which such Data Principal may— (i) withdraw her consent, with the ease of doing so being comparable to that with which such consent was given; (ii) exercise her rights under the Act; and (iii) make a complaint to the Board. | D8: Gazette of India, Extraordinary, Part II, Section 3(i), G.S.R. 846(E), 13 November 2025
A9: DPDP-Act-S5(2) | B9: Digital Personal Data Protection Act, 2023, Section 5(2) | C9: (2) Where a Data Principal has given her consent for the processing of her personal data before the date of commencement of this Act,— (a) the Data Fiduciary shall, as soon as it is reasonably practicable, give to the Data Principal a notice informing her,— (i) the personal data and the purpose for which the same has been processed; (ii) the manner in which she may exercise her rights under sub-section (4) of section 6 and section 13; and (iii) the manner in which the Data Principal may make a complaint to the Board, in such manner and as may be prescribed. (b) the Data Fiduciary may continue to process the personal data until and unless the Data Principal withdraws her consent. | D9: Gazette of India, Extraordinary, Part II, Section 1, No. 25, 11 August 2023
A10: DPDP-Act-S6(1) | B10: Digital Personal Data Protection Act, 2023, Section 6(1) | C10: (1) The consent given by the Data Principal shall be free, specific, informed, unconditional and unambiguous with a clear affirmative action, and shall signify an agreement to the processing of her personal data for the specified purpose and be limited to such personal data as is necessary for such specified purpose. | D10: Gazette of India, Extraordinary, Part II, Section 1, No. 25, 11 August 2023
A11: DPDP-Act-S6(4) | B11: Digital Personal Data Protection Act, 2023, Section 6(4) and Section 6(6) | C11: (4) Where consent given by the Data Principal is the basis of processing of personal data, such Data Principal shall have the right to withdraw her consent at any time, with the ease of doing so being comparable to the ease with which such consent was given. … (6) If a Data Principal withdraws her consent to the processing of personal data under sub-section (5), the Data Fiduciary shall, within a reasonable time, cease and cause its Data Processors to cease processing the personal data of such Data Principal unless such processing without her consent is required or authorised under the provisions of this Act or the rules made thereunder or any other law for the time being in force in India. | D11: Gazette of India, Extraordinary, Part II, Section 1, No. 25, 11 August 2023
A12: DPDP-Act-S6(10) | B12: Digital Personal Data Protection Act, 2023, Section 6(10) | C12: (10) Where a consent given by the Data Principal is the basis of processing of personal data and a question arises in this regard in a proceeding, the Data Fiduciary shall be obliged to prove that a notice was given by her to the Data Principal and consent was given by such Data Principal to the Data Fiduciary in accordance with the provisions of this Act and the rules made thereunder. | D12: Gazette of India, Extraordinary, Part II, Section 1, No. 25, 11 August 2023
A13: DPDP-Rule-4(1) | B13: Digital Personal Data Protection Act, 2023, Section 6(7) and Section 6(9) | C13: (7) The Data Principal may give, manage, review or withdraw her consent to the Data Fiduciary through a Consent Manager. … (9) Every Consent Manager shall be registered with the Board in such manner and subject to such technical, operational, financial and other conditions as may be prescribed. | D13: Gazette of India, Extraordinary, Part II, Section 1, No. 25, 11 August 2023
A14: DPDP-Rule-4(1) | B14: Digital Personal Data Protection Rules, 2025, Rule 4(1) | C14: (1) A person who fulfils the conditions for registration of Consent Managers set out in Part A of First Schedule may apply to the Board for registration as a Consent Manager by furnishing such particulars and such other information and documents as the Board may publish in this behalf on its website. | D14: Gazette of India, Extraordinary, Part II, Section 3(i), G.S.R. 846(E), 13 November 2025
A15: DPDP-Act-S8(1) | B15: Digital Personal Data Protection Act, 2023, Section 8(1) and Section 8(2) | C15: (1) A Data Fiduciary shall, irrespective of any agreement to the contrary or failure of a Data Principal to carry out the duties provided under this Act, be responsible for complying with the provisions of this Act and the rules made thereunder in respect of any processing undertaken by it or on its behalf by a Data Processor. (2) A Data Fiduciary may engage, appoint, use or otherwise involve a Data Processor to process personal data on its behalf for any activity related to offering of goods or services to Data Principals only under a valid contract. | D15: Gazette of India, Extraordinary, Part II, Section 1, No. 25, 11 August 2023
... A63: DPDP-Act-S17(1) | B63: Digital Personal Data Protection Act, 2023, Section 17(3) and Section 17(5) | C63: (3) The Central Government may, having regard to the volume and nature of personal data processed, notify certain Data Fiduciaries or class of Data Fiduciaries, including startups, as Data Fiduciaries to whom the provisions of section 5, sub-sections (3) and (7) of section 8 and sections 10 and 11 shall not apply. … (5) The Central Government may, before expiry of five years from the date of commencement of this Act, by notification, declare that any provision of this Act shall not apply to such Data Fiduciary or classes of Data Fiduciaries for such period as may be specified in the notification. | D63: Gazette of India, Extraordinary, Part II, Section 1, No. 25, 11 August 2023

Sheet Event Playbook
A1: Event Playbook: what starts the clock
A2: When something happens, find the row: the time limit, who acts, and the evidence to keep.
A4: Event | B4: When the clock starts | C4: Time limit | D4: Governance team does | E4: Engineering does | F4: Legal provision | G4: Evidence to keep | H4: Control identifier
A5: Consent is requested | B5: At the request | C5: Notice given with or before the request | D5: Approves the notice text and each language version | E5: Shows the notice first and records the notice version shown to each person | F5: Act Section 5(1); Rules Rule 3 | G5: Record of notice versions shown | H5: DPDP-Act-S5(1)
A6: Consent is withdrawn | B6: At withdrawal | C6: Stop processing within a reasonable time, and make Data Processors stop | D6: Sets the internal time limit | E6: Sends the withdrawal to every system and every Data Processor | F6: Act Section 6(4) to 6(6) | G6: Record of the withdrawal reaching each system | H6: DPDP-Act-S6(4)
